[{'answer1': '{\n  "intentOfThisFunction": "This function is intended to retrieve the value of a function.",\n  "faultLocalization": []\n}', 'money1': False}, {'answer1': '{\n  "intentOfThisFunction": "This function is intended to return the result obtained from the optimizer.",\n  "faultLocalization": [\n    {\n      "lineNumber": 97,\n      "codeContent": "return optimizer.getResult();",\n      "reason": "The code assumes that the optimizer will always have a valid result to return, without checking for null or error conditions. This can potentially lead to a NullPointerException or unexpected behavior if the optimizer fails to produce a result."\n    }\n  ]\n}', 'money1': False, 'answer2': '{\n  "intentOfThisFunction": "This function is intended to return the result obtained from the optimizer.",\n  "faultLocalization": [\n    {\n      "lineNumber": 97,\n      "codeContent": "return optimizer.getResult();",\n      "reason": "The code assumes that the optimizer will always have a valid result to return, without checking for null or error conditions. This can potentially lead to a NullPointerException or unexpected behavior if the optimizer fails to produce a result."\n    },\n    {\n      "lineNumber": 74,\n      "codeContent": "fail(\\"wrong exception caught\\");",\n      "reason": "The code is expecting a specific exception to be thrown but fails the test if any other exception is caught. This can lead to false-positive test failures and inaccurate test results."\n    },\n    {\n      "lineNumber": 82,\n      "codeContent": "fail(\\"wrong exception caught\\");",\n      "reason": "Similar to the previous line, this code also fails the test if any exception other than the expected one is caught. This can result in false-positive test failures."\n    },\n    {\n      "lineNumber": 71,\n      "codeContent": "fail(\\"an exception should have been thrown\\");",\n      "reason": "The code expects an exception to be thrown but does not provide any information about the expected exception. As a result, the test failure message may not be meaningful or provide enough information to debug the issue."\n    },\n    {\n      "lineNumber": 53,\n      "codeContent": "public void testQuinticMin() throws MathException {",\n      "reason": "The test method is declared to throw MathException but none of the code within the method actually throws or handles this exception. This can lead to potential unhandled exceptions and unexpected test behavior."\n    }\n  ]\n}'}]