[{'answer1': 'The JSON analysis for the code snippet is as follows:\njson\nCopy code\n{\n    "intentOfThisFunction": "The function \'verify\' is intended to begin a timer and verify the given data until the timer is counting or the verification succeeds. If any verification error occurs during this process, it is caught and handled. At the end, if an error exists, it is thrown.",\n    "faultLocalization": [\n        {\n            "lineNumber": 83,\n            "codeContent": "if (returnOnSuccess) {84:return;85:}",\n            "reason": "If \'returnOnSuccess\' is true, the function will return immediately after one successful verification, even if the timer is still counting. If it\'s not the intended behavior, it could lead to unexpected results."\n        },\n        {\n            "lineNumber": 89,\n            "codeContent": "error = handleVerifyException(e);",\n            "reason": "The same error handling method is called for different types of exceptions. This might be a potential issue if specific handling is required for different exceptions."\n        },\n        {\n            "lineNumber": 92,\n            "codeContent": "error = handleVerifyException(e);",\n            "reason": "Similar to above, the same error handling method is called for different types of exceptions. Specific handling may be needed for different exceptions."\n        },\n        {\n            "lineNumber": 96,\n            "codeContent": "if (error != null) {97:throw error;",\n            "reason": "There\'s a potential for AssertionError to be thrown from this method. This may or may not be the desired behavior, but it should be noted as it can disrupt the control flow of the calling function."\n        }\n    ]\n}\nPlease note that without more context (such as the methods this function is calling, the overall class or project this function is part of, etc.), this analysis might be incomplete or inaccurate. The identified potential bugs depend heavily on the intended behavior of the code.'}]