[{'answer1': 'The following code appears to be part of a test or verification utility. It tries to verify some data and provides the option to exit on success or keep going and accumulating errors. Here\'s my analysis in JSON format:\njson\nCopy code\n{\n    "intentOfThisFunction": "This function seems to be for verification of some input data. It uses a delegate to perform the verification, and can be configured to return immediately upon successful verification. If verification fails, it handles the error and optionally rethrows it at the end. It seems to loop over this verification until a timer runs out.",\n    "faultLocalization": [\n        {\n            "lineNumber": 79,\n            "codeContent": "while (timer.isCounting()) {",\n            "reason": "If the delegate.verify(data) doesn\'t change the state that timer.isCounting() relies on, or there is no other way to stop the timer, this could be an infinite loop."\n        },\n        {\n            "lineNumber": 86,\n            "codeContent": "error = null;",\n            "reason": "This line resets the error variable to null regardless of any errors that might have occurred in previous iterations of the while loop. If the loop doesn\'t break and an error occurs, that error will be lost."\n        },\n        {\n            "lineNumber": 97,\n            "codeContent": "throw error;",\n            "reason": "This line throws an error only if the last verification resulted in an error. If there were previous errors in other iterations, they will not cause the function to throw an error."\n        }\n    ]\n}\nKeep in mind that these potential bugs depend on the specifics of your code and its use case. They might not be bugs at all if the function is being used as intended. For example, if the timer always eventually stops counting, there won\'t be an infinite loop. Similarly, if you don\'t care about errors from previous verifications, resetting and only throwing the last error might not be a problem.'}]